<mujocoinclude model="tams_ur5_setup">
    <!-- <size njmax="500" nconmax="100" /> -->
    <!-- <worldbody> -->
    <body mocap="true" name="ur5_mocap" pos="0 0 0">
        <geom conaffinity="0" contype="0" pos="0 0 0" rgba="0 0.5 0 0.7" size="0.005 0.005 0.005" type="box"></geom>
        <geom conaffinity="0" contype="0" pos="0 0 0" rgba="0 0.5 0 0.1" size="1 0.005 0.005" type="box"></geom>
        <geom conaffinity="0" contype="0" pos="0 0 0" rgba="0 0.5 0 0.1" size="0.005 1 0.001" type="box"></geom>
        <geom conaffinity="0" contype="0" pos="0 0 0" rgba="0 0.5 0 0.1" size="0.005 0.005 1" type="box"></geom>
    </body>

    <body name="floor" pos="0 0 0">
        <inertial pos="2.5 2.5 0" mass="2000" diaginertia="1 1 1" />
        <geom size="2.5 2.5825 0.0005" pos="2.5 2.4175 0" type="box" />
        <body name="wall" pos="0 0 0">
            <inertial pos="-0.06 2.5 1.5" mass="2000" diaginertia="1 1 1" />
            <geom size="0.06 2.5 1.5" pos="-0.06 2.5 1.5" type="box" rgba="1 1 1 1" />
            <body name="ur5_mount_plate" pos="0 0.7245 1.05">
                <inertial pos="0 0.7245 1.05" mass="0" diaginertia="0 0 0" />
                <body name="ur5_mount" pos="0.2255 -0.025 0.032" quat="0 0 0 1">
                    <inertial pos="0.151009 -1.15872e-06 -0.0859331" quat="0.930724 2.56125e-05 -0.365722 -0.000134195" mass="8.3594" diaginertia="0.0794152 0.0757292 0.0408253" />
                    <geom pos="-0.0245 -0.09 -0.28" type="mesh" rgba="0.6 0.6 0.6 1" mesh="ur5_mount_binary_v3" />
                    <body name="ur5_base_link" pos="0 0 0.003" quat="0.707107 0 0 0.707107">
                        <inertial pos="0 0 0" quat="0.5 0.5 -0.5 0.5" mass="4" diaginertia="0.0072 0.00443333 0.00443333" />
                        <geom type="mesh" rgba="0.7 0.7 0.7 1" mesh="base" />
                        <body name="ur5_shoulder_link" pos="0 0 0.089159">
                            <inertial pos="0 0 0" mass="3.7" diaginertia="0.0102675 0.0102675 0.00666" />
                            <joint name="ur5_shoulder_pan_joint" pos="0 0 0" axis="0 0 1" limited="true" range="-6.28119 6.28119" />
                            <geom type="mesh" rgba="0.7 0.7 0.7 1" mesh="shoulder" />
                            <body name="ur5_upper_arm_link" pos="0 0.13585 0" quat="0.707107 0 0.707107 0">
                                <inertial pos="0 0 0.28" mass="8.393" diaginertia="0.226891 0.226891 0.0151074" />
                                <joint name="ur5_shoulder_lift_joint" pos="0 0 0" axis="0 1 0" limited="true" range="-6.28119 6.28119" />
                                <geom type="mesh" rgba="0.7 0.7 0.7 1" mesh="upperarm" />
                                <body name="ur5_forearm_link" pos="0 -0.1197 0.425">
                                    <inertial pos="0 0 0.25" mass="2.275" diaginertia="0.0494433 0.0494433 0.004095" />
                                    <joint name="ur5_elbow_joint" pos="0 0 0" axis="0 1 0" limited="true" range="-3.14159 3.14159" />
                                    <geom type="mesh" rgba="0.7 0.7 0.7 1" mesh="forearm" />
                                    <body name="ur5_wrist_1_link" pos="0 0 0.39225" quat="0.707107 0 0.707107 0">
                                        <inertial pos="0 0 0" quat="0.5 0.5 -0.5 0.5" mass="1.219" diaginertia="0.21942 0.111173 0.111173" />
                                        <joint name="ur5_wrist_1_joint" pos="0 0 0" axis="0 1 0" limited="true" range="-6.28119 6.28119" />
                                        <geom type="mesh" rgba="0.7 0.7 0.7 1" mesh="wrist1" />
                                        <body name="ur5_wrist_2_link" pos="0 0.093 0">
                                            <inertial pos="0 0 0" quat="0.5 0.5 -0.5 0.5" mass="1.219" diaginertia="0.21942 0.111173 0.111173" />
                                            <joint name="ur5_wrist_2_joint" pos="0 0 0" axis="0 0 1" limited="true" range="-3.14159 3.14159" />
                                            <geom type="mesh" rgba="0.7 0.7 0.7 1" mesh="wrist2_rounded" />
                                            <body name="ur5_wrist_3_link" pos="0 0 0.09465">
                                                <body name="ur5_vision_cam_wrist" pos="0 -0.07 0.0">
                                                    <site name="ur5_vision_cam_wrist" pos="0 0 0.085"  size="0.003" rgba="1 0 0 1" type="sphere"/>
                                                    <camera quat="0.08715574 0.9961947 0.0 0.0" fovy="37.0" name="vision_cam_wrist" pos="0.0 0.0 0.085"/>
                                                    <geom name="ur5_vision_cam_wrist" size="0.044 0.044 0.0045" type="box" rgba="0.2 0.2 0.2 0" contype="0" conaffinity="0"/>
                                                </body>
                                                <inertial pos="0 0 0" quat="0.5 0.5 -0.5 0.5" mass="0.1879" diaginertia="0.033822 0.0171365 0.0171365" />
                                                <joint name="ur5_wrist_3_joint" pos="0 0 0" axis="0 1 0" limited="true" range="-6.28119 6.28119" />
                                                <geom type="mesh" rgba="0.7 0.7 0.7 1" mesh="wrist3" />
                                                <body name="ur5_ee_link" pos="0 0.0823 0" quat="0.707107 0 0 0.707107">
                                                    <inertial pos="-0.01 0 0" mass="0.001" diaginertia="1.66667e-08 1.66667e-08 1.66667e-08" />
                                                    <geom size="0.005 0.005 0.005" pos="-0.01 0 0" type="box" />
                                                    <body name="ft_adapter" pos="0.0045 0 0" quat="0.707107 0 0.707107 0">
                                                        <inertial pos="0 0 0" quat="0.5 0.5 -0.5 0.5" mass="0.2" diaginertia="0.00333333 0.00270833 0.000708333" />
                                                        <geom size="0.044 0.044 0.0045" type="box" rgba="0.2 0.2 0.2 1" />
                                                        <body name="mounted_holder" pos="0 0 0">
                                                            <inertial pos="0 -0.0045 -0.045" quat="0.571606 0.419998 0.417573 0.567892" mass="0.041" diaginertia="0.00019878 0.00019878 0.00019878" />
                                                            <geom pos="0 0 -0.0045" quat="0 -1 0 0" type="mesh" rgba="0.2 0.2 0.2 1" mesh="holder" />
                                                            <body name="r200_camera_link" pos="0.0806 0.0445 -0.0127" quat="0 -0.866025 0 -0.5">
                                                                <inertial pos="0 0 0" quat="0 0.707107 0 0.707107" mass="0.039" diaginertia="2.8169e-05 2.7958e-05 1.004e-06" />
                                                                <geom pos="-0.0078 0.043 0" type="mesh" rgba="0 0.3 0.6 1" mesh="r200" />
                                                            </body>
                                                        </body>
                                                    </body>
                                                    <body name="ft_fts_robotside" pos="0.009 0 0" quat="0 0.707107 0 0.707107">
                                                        <inertial pos="0 0 0.01875" quat="0.5 0.5 -0.5 0.5" mass="0.65" diaginertia="0.00117 0.000661172 0.000661172" />
                                                        <geom type="mesh" mesh="robotiq_fts150" />
                                                        <body name="ft_robotiq_ft_frame_id" pos="0 0 0.01625">
                                                            <inertial pos="0 0 0.01625" mass="0" diaginertia="0 0 0" />
                                                        </body>
                                                        <body name="ft_fts_toolside" pos="0 0 0.0375">
                                                            <inertial pos="0 0 0.0375" mass="0" diaginertia="0 0 0" />
                                                            <body name="tool0" pos="0 0 0.0205" quat="0.707107 0 -0.707107 0">
                                                                <inertial pos="0 0 0.0205" quat="0.707107 0 -0.707107 0" mass="0" diaginertia="0 0 0" />
                                                                <body name="s_model_palm" pos="0.057 0 0" quat="0 0.707107 0.707107 0">
                                                                    <inertial pos="-0.00134236 0.00263073 -1.01672e-08" quat="0.489887 0.489849 0.509908 0.509954" mass="1.20044" diaginertia="0.00263541 0.00218876 0.00210987" />
                                                                    <geom name="s_model_palm" type="mesh" rgba="0.2 0.2 0.2 1" mesh="palm" />
                                                                    <!-- <body name="pusher" pos="0.0 0.0 0.0">
                                                                        <geom name="pusher" type="mesh" rgba="0.7 0.7 0.7 1" mesh="pusher" />
                                                                    </body> -->
                                                                    <body name="s_model_finger_1_link_0" pos="-0.0455 0.0214 0.036" quat="-2.59838e-06 0.706825 0.707388 2.59631e-06">
                                                                        <inertial pos="0 0 0" quat="0.707145 0.707067 -0.0011614 -0.000375819" mass="0.05" diaginertia="0.00393333 0.00393333 0.00393333" />
                                                                        <!-- <joint name="s_model_palm_finger_1_joint" pos="0 0 0" axis="0 1 0" limited="true" range="-0.1784 0.192" /> -->
                                                                        <!-- <joint name="s_model_palm_finger_1_joint" pos="0 0 0" axis="0 1 0" limited="true" range="-0. 0." /> -->
                                                                        <geom name="s_model_finger_1_link_0" pos="0.02 0 0" type="mesh" rgba="0.2 0.2 0.2 1" mesh="link_0" />
                                                                        <body name="s_model_finger_1_link_1" pos="0.02 0 0">
                                                                            <inertial pos="0 0 0" quat="0.478816 0.503501 0.521199 0.495554" mass="0.15" diaginertia="0.00567167 0.00567167 0.00567167" />
                                                                            <!-- <joint name="s_model_finger_1_joint_1" pos="0 0 0" axis="0 0 1" limited="true" range="0.0495 1.2218" /> -->
                                                                            <joint name="s_model_finger_1_joint_1" pos="0 0 0" axis="0 0 1" limited="true" range="1.98 1.981" />
                                                                            <geom name="s_model_finger_1_link_1" pos="0.05 -0.028 0" quat="0.96639 0 0 -0.257081" type="mesh" rgba="0.2 0.2 0.2 1" mesh="link_1" />
                                                                            <body name="s_model_finger_1_link_2" pos="0.05 -0.028 0" quat="0.96639 0 0 -0.257081">
                                                                                <inertial pos="0 0 0" quat="0.478816 0.503501 0.521199 0.495554" mass="0.15" diaginertia="0.00567167 0.00567167 0.00567167" />
                                                                                <!-- <joint name="s_model_finger_1_joint_2" pos="0 0 0" axis="0 0 1" limited="true" range="0 1.5708" /> -->
                                                                                <joint name="s_model_finger_1_joint_2" pos="0 0 0" axis="0 0 1" limited="true" range="0 0.001" />
                                                                                <geom name="s_model_finger_1_link_2" pos="0.039 0 0.0075" type="mesh" rgba="0.2 0.2 0.2 1" mesh="link_2" />
                                                                                <body name="s_model_finger_1_link_3" pos="0.039 0 0">
                                                                                    <inertial pos="0 0 0" quat="0.614353 0.390886 -0.585309 0.35664" mass="0.05" diaginertia="0.00163315 0.00136097 0.000726883" />
                                                                                    <!-- <joint name="s_model_finger_1_joint_3" pos="0 0 0" axis="0 0 1" limited="true" range="-1.2217 -0.0523" /> -->
                                                                                    <joint name="s_model_finger_1_joint_3" pos="0 0 0" axis="0 0 1" limited="true" range="-0.341 -0.34" />
                                                                                    <geom name="s_model_finger_1_link_3" quat="0.96639 0 0 0.257081" type="mesh" rgba="0.2 0.2 0.2 1" mesh="link_3" />
                                                                                </body>
                                                                            </body>
                                                                        </body>
                                                                    </body>
                                                                    <body name="s_model_finger_2_link_0" pos="-0.0455 0.0214 -0.036" quat="-2.59838e-06 0.706825 0.707388 2.59631e-06">
                                                                        <inertial pos="0 0 0" quat="0.707145 0.707067 -0.0011614 -0.000375819" mass="0.05" diaginertia="0.00393333 0.00393333 0.00393333" />
                                                                        <!-- <joint name="s_model_palm_finger_2_joint" pos="0 0 0" axis="0 1 0" limited="true" range="-0.192 0.1784" /> -->
                                                                        <!-- <joint name="s_model_palm_finger_2_joint" pos="0 0 0" axis="0 1 0" limited="true" range="0. 0." /> -->
                                                                        <geom name="s_model_finger_2_link_0" pos="0.02 0 0" type="mesh" rgba="0.2 0.2 0.2 1" mesh="link_0" />
                                                                        <body name="s_model_finger_2_link_1" pos="0.02 0 0">
                                                                            <inertial pos="0 0 0" quat="0.478816 0.503501 0.521199 0.495554" mass="0.15" diaginertia="0.00567167 0.00567167 0.00567167" />
                                                                            <!-- <joint name="s_model_finger_2_joint_1" pos="0 0 0" axis="0 0 1" limited="true" range="0.0495 1.2218" /> -->
                                                                            <joint name="s_model_finger_2_joint_1" pos="0 0 0" axis="0 0 1" limited="true" range="1.98 1.981" />
                                                                            <geom name="s_model_finger_2_link_1" pos="0.05 -0.028 0" quat="0.96639 0 0 -0.257081" type="mesh" rgba="0.2 0.2 0.2 1" mesh="link_1" />
                                                                            <body name="s_model_finger_2_link_2" pos="0.05 -0.028 0" quat="0.96639 0 0 -0.257081">
                                                                                <inertial pos="0 0 0" quat="0.478816 0.503501 0.521199 0.495554" mass="0.15" diaginertia="0.00567167 0.00567167 0.00567167" />
                                                                                <!-- <joint name="s_model_finger_2_joint_2" pos="0 0 0" axis="0 0 1" limited="true" range="0 1.5708" /> -->
                                                                                <joint name="s_model_finger_2_joint_2" pos="0 0 0" axis="0 0 1" limited="true" range="0 0.001" />
                                                                                <geom name="s_model_finger_2_link_2" pos="0.039 0 0.0075" type="mesh" rgba="0.2 0.2 0.2 1" mesh="link_2" />
                                                                                <body name="s_model_finger_2_link_3" pos="0.039 0 0">
                                                                                    <inertial pos="0 0 0" quat="0.614353 0.390886 -0.585309 0.35664" mass="0.05" diaginertia="0.00163315 0.00136097 0.000726883" />
                                                                                    <!-- <joint name="s_model_finger_2_joint_3" pos="0 0 0" axis="0 0 1" limited="true" range="-1.2217 -0.0523" /> -->
                                                                                    <joint name="s_model_finger_2_joint_3" pos="0 0 0" axis="0 0 1" limited="true" range="-0.341 -0.34" />
                                                                                    <geom name="s_model_finger_2_link_3" quat="0.96639 0 0 0.257081" type="mesh" rgba="0.2 0.2 0.2 1" mesh="link_3" />
                                                                                </body>
                                                                            </body>
                                                                        </body>
                                                                    </body>
                                                                    <body name="s_model_finger_middle_link_0" pos="0.0455 0.0214 0" quat="0.707388 0 0 0.706825">
                                                                        <inertial pos="0 0 0" quat="0.707145 0.707067 -0.0011614 -0.000375819" mass="0.05" diaginertia="0.00393333 0.00393333 0.00393333" />
                                                                        <geom name="s_model_finger_middle_link_0" pos="0.02 0 0" type="mesh" rgba="0.2 0.2 0.2 1" mesh="link_0" />
                                                                        <body name="s_model_finger_middle_link_1" pos="0.02 0 0">
                                                                            <inertial pos="0 0 0" quat="0.478816 0.503501 0.521199 0.495554" mass="0.15" diaginertia="0.00567167 0.00567167 0.00567167" />
                                                                            <!-- <joint name="s_model_finger_middle_joint_1" pos="0 0 0" axis="0 0 1" limited="true" range="0.0495 1.2218" /> -->
                                                                            <joint name="s_model_finger_middle_joint_1" pos="0 0 0" axis="0 0 1" limited="true" range="2.92 2.921" />
                                                                            <geom name="s_model_finger_middle_link_1" pos="0.05 -0.028 0" quat="0.96639 0 0 -0.257081" type="mesh" rgba="0.2 0.2 0.2 1" mesh="link_1" />
                                                                            <body name="s_model_finger_middle_link_2" pos="0.05 -0.028 0" quat="0.96639 0 0 -0.257081">
                                                                                <inertial pos="0 0 0" quat="0.478816 0.503501 0.521199 0.495554" mass="0.15" diaginertia="0.00567167 0.00567167 0.00567167" />
                                                                                <!-- <joint name="s_model_finger_middle_joint_2" pos="0 0 0" axis="0 0 1" limited="true" range="0 1.5708" /> -->
                                                                                <joint name="s_model_finger_middle_joint_2" pos="0 0 0" axis="0 0 1" limited="true" range="0.32 0.321" />
                                                                                <geom name="s_model_finger_middle_link_2" pos="0.039 0 0.0075" type="mesh" rgba="0.2 0.2 0.2 1" mesh="link_2" />
                                                                                <body name="s_model_finger_middle_link_3" pos="0.039 0 0">
                                                                                    <inertial pos="0 0 0" quat="0.614353 0.390886 -0.585309 0.35664" mass="0.05" diaginertia="0.00163315 0.00136097 0.000726883" />
                                                                                    <!-- <joint name="s_model_finger_middle_joint_3" pos="0 0 0" axis="0 0 1" limited="true" range="-1.2217 -0.0523" /> -->
                                                                                    <joint name="s_model_finger_middle_joint_3" pos="0 0 0" axis="0 0 1" limited="true" range="-0.121 -0.12" />
                                                                                    <geom name="s_model_finger_middle_link_3" quat="0.96639 0 0 0.257081" type="mesh" rgba="0.2 0.2 0.2 1" mesh="link_3" />
                                                                                </body>
                                                                            </body>
                                                                        </body>
                                                                    </body>
                                                                    <body name="pusher" pos="0.0 0.057 0.0">
                                                                        <inertial pos="0. 0. 0." mass="0" diaginertia="0 0 0" />
                                                                        <geom name="pusher" type="mesh" rgba="0.7 0.7 0.7 1" mesh="pusher"/>
                                                                    </body>
                                                                    <body name="s_model_tool0" pos="0 0.0875 0" quat="0.707141 0 0 0.707073">
                                                                        <inertial pos="0 0.0875 0" quat="0.707141 0 0 0.707073" mass="0" diaginertia="0 0 0" />
                                                                    </body>
                                                                </body>
                                                                <site name="pusher" pos="0.02 0 0" rgba="0 0 0 0" size="0.02 0.02 0.02"></site>
                                                            </body>
                                                            <body name="s_model_adapter" pos="0 0 0.015">
                                                                <inertial pos="0 0 0" quat="0.5 0.5 -0.5 0.5" mass="0.2" diaginertia="0.00333333 0.00270833 0.000708333" />
                                                                <geom size="0.06 0.0175" type="cylinder" rgba="0.2 0.2 0.2 1" />
                                                                <geom size="0.0175 0.0175 0.0175" pos="0.0725 0 0" type="box" rgba="0.2 0.2 0.2 1" />
                                                            </body>
                                                        </body>
                                                    </body>
                                                    <body name="plug_collision_model_link_1" pos="0 0 0">
                                                        <inertial pos="0 0 0" quat="0.5 0.5 -0.5 0.5" mass="0.2" diaginertia="0.00333333 0.00270833 0.000708333" />
                                                        <geom size="0.04 0.05 0.0375" pos="0.08 -0.05 0" type="box" />
                                                    </body>
                                                    <body name="plug_collision_model_link_2" pos="0 0 0">
                                                        <inertial pos="0 0 0" quat="0.5 0.5 -0.5 0.5" mass="0.2" diaginertia="0.00333333 0.00270833 0.000708333" />
                                                        <geom size="0.015 0.045 0.06" pos="0.025 -0.025 0.06" type="box" />
                                                    </body>
                                                </body>
                                                <body name="ur5_tool0" pos="0 0.0823 0" quat="0.707107 -0.707107 0 0">
                                                    <inertial pos="0 0.0823 0" quat="0.707107 -0.707107 0 0" mass="0" diaginertia="0 0 0" />
                                                </body>
                                            </body>
                                        </body>
                                    </body>
                                </body>
                            </body>
                        </body>
                        <body name="ur5_base" pos="0 0 0" quat="0 0 0 -1">
                            <inertial pos="0 0 0" quat="0 0 0 -1" mass="0" diaginertia="0 0 0" />
                        </body>
                    </body>
                </body>
            </body>
            <body name="april_tag_ur5" pos="-0.009 0.74 1.505" quat="0.503736 -0.503736 0.496236 -0.496236">
                <inertial pos="0 0 0" mass="2000" diaginertia="1 1 1" />
                <geom size="0.083 0.083 0.005" type="box" rgba="0.6 0.6 0.6 1" />
            </body>
            <body name="clock" pos="0.03 0.82 1.93" quat="0.5 -0.5 0.5 -0.5">
                <inertial pos="0 0 0" mass="2000" diaginertia="1 1 1" />
                <geom size="0.14 0.03" type="cylinder" rgba="0.6 0.6 0.6 1" />
            </body>
        </body>
        <body name="side_wall" pos="2.5 -0.225 1.5">
            <inertial pos="0 0 0" mass="2000" diaginertia="1 1 1" />
            <geom size="2.5 0.06 1.5" type="box" rgba="1 1 1 1" />
        </body>
        <body name="small_wall" pos="0.07 -0.0825 1.5">
            <inertial pos="0 0 0" mass="2000" diaginertia="1 1 1" />
            <geom size="0.165 0.1525 1.5" type="box" rgba="1 1 1 1" />
        </body>
        <body name="cable_duct" pos="0.475 -0.135 1.5">
            <inertial pos="0 0 0" mass="2000" diaginertia="1 1 1" />
            <geom size="0.135 0.1 1.5" type="box" rgba="0.6 0.6 0.6 1" />
        </body>
        <body name="table" pos="0.70 0.74 0">
            <inertial pos="0 0 0.39" mass="10" diaginertia="1 1 1" />
            <geom name="table" size="0.4 0.5 0.39" pos="0 0 0.39" type="box" rgba="0.87 0.72 0.53 0.1" />
            <body name="table_top" pos="0 0 0.78">
                <inertial pos="0 0 0.78" mass="0" diaginertia="0 0 0" />
                <body name="table_gym" pos="-0.5 -0.6 0">
                    <inertial pos="-0.5 -0.6 0" mass="0" diaginertia="0 0 0" />
                </body>
                <body name="table_gym_ddpg" pos="-0.78 1.35 0" quat="0.707107 0 0 -0.707107">
                    <inertial pos="-0.78 1.35 0" quat="0.707107 0 0 -0.707107" mass="0" diaginertia="0 0 0" />
                </body>
                <body name="table_tag" pos="0.3 0.4 0" quat="0 0 0 1">
                    <inertial pos="0.3 0.4 0" quat="0 0 0 1" mass="0" diaginertia="0 0 0" />
                </body>
            </body>
        </body>
        <body name="shelf" pos="0.2 1 1.25">
            <inertial pos="1.7 0 0" mass="60" diaginertia="1 1 1" />
            <geom size="0.27 1.07 1.25" pos="0 1.7 0" type="box" rgba="0.6 0.6 0.6 1" />
        </body>
    </body>
    <body name="map" pos="0.9 1.3 0" quat="0.987227 0 0 -0.159318">
        <inertial pos="0.9 1.3 0" quat="0.987227 0 0 -0.159318" mass="0" diaginertia="0 0 0" />
    </body>
    <!-- </worldbody> -->
</mujocoinclude>
